<?xml version="1.0" ?>
<sdf version="1.5">
<!-- turtlebot3 -->
  <model name="turtlebot3_burger">
    <pose>0.0 0.0 0.0 0.0 0.0 0.0</pose>

    <link name="base_footprint"/>

    <link name="base_link">

      <inertial>
        <pose>-0.32 0 0.70 0 0 0</pose>
        <inertia>
          <ixx>72.397393</ixx>
          <ixy>4.686399e-09</ixy>
          <ixz>-1.09525703e-07</ixz>
          <iyy>72.397393</iyy>
          <iyz>2.8582649e-08</iyz>
          <izz>65.3050163</izz>
        </inertia>
        <mass>82.573504</mass>
      </inertial>

      <collision name="base_collision">
        <pose>-0.32 0 0.70 0 0 0</pose>
        <geometry>
          <box>
            <size>1.40 1.40 1.40</size>
          </box>
        </geometry>
      </collision>

      <visual name="base_visual">
        <pose>-0.32 0 0 0 0 0</pose>
        <geometry>
          <mesh>
            <uri>meshes/bases/burger_base.stl</uri>
            <scale>0.01 0.01 0.01</scale>
          </mesh>
        </geometry>
        <material>
          <ambient>0.3 0.3 0.3 1.0</ambient>
          <diffuse>0.3 0.3 0.3 1.0</diffuse>
        </material>
      </visual>
    </link> 

    <link name="imu_link">
      <sensor name="tb3_imu" type="imu">
        <always_on>true</always_on>
        <update_rate>200</update_rate>
        <imu>
          <angular_velocity>
            <x>
              <noise type="gaussian">
                <mean>0.0</mean>
                <stddev>2e-4</stddev>
              </noise>
            </x>
            <y>
              <noise type="gaussian">
                <mean>0.0</mean>
                <stddev>2e-4</stddev>
              </noise>
            </y>
            <z>
              <noise type="gaussian">
                <mean>0.0</mean>
                <stddev>2e-4</stddev>
              </noise>
            </z>
          </angular_velocity>
          <linear_acceleration>
            <x>
              <noise type="gaussian">
                <mean>0.0</mean>
                <stddev>1.7e-2</stddev>
              </noise>
            </x>
            <y>
              <noise type="gaussian">
                <mean>0.0</mean>
                <stddev>1.7e-2</stddev>
              </noise>
            </y>
            <z>
              <noise type="gaussian">
                <mean>0.0</mean>
                <stddev>1.7e-2</stddev>
              </noise>
            </z>
          </linear_acceleration>
        </imu>

        <plugin filename="libignition-gazebo-imu-system.so" 
          name="ignition::gazebo::systems::Imu">  
          <ros>
            <!-- <namespace>/tb3</namespace> -->
            <remapping>~/out:=imu</remapping>
          </ros>
        </plugin>
      </sensor>
    </link>

    <link name="base_scan">
      <inertial>
        <pose>-0.20 0 1.61 0 0 0</pose>
        <inertia>
          <ixx>0.01</ixx>
          <ixy>0.000</ixy>
          <ixz>0.000</ixz>
          <iyy>0.01</iyy>
          <iyz>0.000</iyz>
          <izz>0.01</izz>
        </inertia>
        <mass>1.14</mass>
      </inertial>

      <collision name="lidar_sensor_collision">
        <pose>-0.20 0 1.61 0 0 0</pose>
        <geometry>
          <cylinder>
            <radius>0.508</radius>
            <length>0.55</length>
          </cylinder>
        </geometry>
      </collision>

      <visual name="lidar_sensor_visual">
        <pose>-0.32 0 1.71 0 0 0</pose>
        <geometry>
          <mesh>
            <uri>meshes/sensors/lds.stl</uri>
            <scale>0.01 0.01 0.01</scale>
          </mesh>
        </geometry>
        <material>
          <ambient>0.2 0.2 0.2 1.0</ambient>
          <diffuse>0.2 0.2 0.2 1.0</diffuse>
        </material>
      </visual> 

      <sensor name="hls_lfcd_lds" type="ray">
        <always_on>true</always_on>
        <visualize>true</visualize>
        <pose>-0.32 0 1.71 0 0 0</pose>
        <update_rate>5</update_rate>
        <ray>
          <scan>
            <horizontal>
              <samples>360</samples>
              <resolution>1.000000</resolution>
              <min_angle>0.000000</min_angle>
              <max_angle>6.280000</max_angle>
            </horizontal>
          </scan>
          <range>
            <min>1.20</min>
            <max>35.0</max>
            <resolution>0.15</resolution>
          </range>
          <noise>
            <type>gaussian</type>
            <mean>0.0</mean>
            <stddev>0.01</stddev>
          </noise>
        </ray>
        <plugin filename="libignition-gazebo-sensors-system.so" name="ignition::gazebo::systems::Sensors">
          <ros>
            <!-- <namespace>/tb3</namespace> -->
            <remapping>~/out:=scan</remapping>
          </ros>
          <output_type>sensor_msgs/LaserScan</output_type>
          <frame_name>base_scan</frame_name>
        </plugin>
      </sensor>
    </link>

    <link name="wheel_left_link">
      <inertial>
        <pose>0 0.8 0.23 -1.57 0 0</pose>
        <inertia>
          <ixx>1.8158194e-02</ixx>
          <ixy>-9.3392e-11</ixy>
          <ixz>1.04909e-10</ixz>
          <iyy>3.2922126e-02</iyy>
          <iyz>5.75694e-10</iyz>
          <izz>1.8158194e-02</izz>
        </inertia>
        <mass>0.28498940</mass>
      </inertial>

      <collision name="wheel_left_collision">
        <pose>0 0.8 0.23 -1.57 0 0</pose>
        <geometry>
          <cylinder>
            <radius>0.33</radius>
            <length>0.18</length>
          </cylinder>
        </geometry>
        <surface>
          <!-- This friction pamareter don't contain reliable data!! -->
          <friction>
            <ode>
              <mu>100000.0</mu>
              <mu2>100000.0</mu2>
              <fdir1>0 0 0</fdir1>
              <slip1>0.0</slip1>
              <slip2>0.0</slip2>
            </ode>
          </friction>
          <contact>
            <ode>
              <soft_cfm>0</soft_cfm>
              <soft_erp>0.2</soft_erp>
              <kp>1e+5</kp>
              <kd>1</kd>
              <max_vel>0.01</max_vel>
              <min_depth>0.001</min_depth>
            </ode>
          </contact>
        </surface>
      </collision>

      <visual name="wheel_left_visual">
        <pose>0 0.8 0.23 0 0 0</pose>
        <geometry>
          <mesh>
            <uri>meshes/wheels/left_tire.stl</uri>
            <scale>0.01 0.01 0.01</scale>
          </mesh>
        </geometry>
        <material>
          <ambient>0.2 0.2 0.2 1.0</ambient>
          <diffuse>0.2 0.2 0.2 1.0</diffuse>
        </material>
      </visual>
    </link> 

    <link name="wheel_right_link">

      <inertial>
        <pose>0.0 -0.8 0.23 -1.57 0 0</pose>
        <inertia>
          <ixx>1.8158194e-02</ixx>
          <ixy>-9.3392e-11</ixy>
          <ixz>1.04909e-10</ixz>
          <iyy>3.2922126e-02</iyy>
          <iyz>5.75694e-10</iyz>
          <izz>1.8158194e-02</izz>
        </inertia>
        <mass>0.28498940</mass>
      </inertial>

      <collision name="wheel_right_collision">
        <pose>0.0 -0.8 0.23 -1.57 0 0</pose>
        <geometry>
          <cylinder>
            <radius>0.33</radius>
            <length>0.18</length>
          </cylinder>
        </geometry>
        <surface>
          <!-- This friction pamareter don't contain reliable data!! -->
          <friction>
            <ode>
              <mu>100000.0</mu>
              <mu2>100000.0</mu2>
              <fdir1>0 0 0</fdir1>
              <slip1>0.0</slip1>
              <slip2>0.0</slip2>
            </ode>
          </friction>
          <contact>
            <ode>
              <soft_cfm>0</soft_cfm>
              <soft_erp>0.2</soft_erp>
              <kp>1e+5</kp>
              <kd>1</kd>
              <max_vel>0.01</max_vel>
              <min_depth>0.001</min_depth>
            </ode>
          </contact>
        </surface>
      </collision>

      <visual name="wheel_right_visual">
        <pose>0.0 -0.8 0.23 0 0 0</pose>
        <geometry>
          <mesh>
            <uri>meshes/wheels/right_tire.stl</uri>
            <scale>0.01 0.01 0.01</scale>
          </mesh>
        </geometry>
        <material>
          <ambient>0.2 0.2 0.2 1.0</ambient>
          <diffuse>0.2 0.2 0.2 1.0</diffuse>
        </material>
      </visual>
    </link> 

    <link name='caster_back_link'>
      <pose>-0.81 0 -0.04 -1.57 0 0</pose>
      <inertial>
        <mass>0.05</mass>
        <inertia>
          <ixx>0.01</ixx>
          <ixy>0.000</ixy>
          <ixz>0.000</ixz>
          <iyy>0.01</iyy>
          <iyz>0.000</iyz>
          <izz>0.01</izz>
        </inertia>
      </inertial>
      <collision name='collision'>
        <geometry>
          <sphere>
            <radius>0.05</radius>
          </sphere>
        </geometry>
        <surface>
          <contact>
            <ode>
              <soft_cfm>0</soft_cfm>
              <soft_erp>0.2</soft_erp>
              <kp>1e+5</kp>
              <kd>1</kd>
              <max_vel>0.01</max_vel>
              <min_depth>0.001</min_depth>
            </ode>
          </contact>
        </surface>
      </collision>
    </link>

    <joint name="base_joint" type="fixed">
      <parent>base_footprint</parent>
      <child>base_link</child>
      <pose>0.0 0.0 0.10 0 0 0</pose>
    </joint>

    <joint name="wheel_left_joint" type="revolute">
      <parent>base_link</parent>
      <child>wheel_left_link</child>
      <pose>0.0 0.8 0.23 -1.57 0 0</pose>
      <axis>
        <xyz>0 0 1</xyz>
      </axis>
    </joint>

    <joint name="wheel_right_joint" type="revolute">
      <parent>base_link</parent>
      <child>wheel_right_link</child>
      <pose>0.0 -0.8 0.23 -1.57 0 0</pose>
      <axis>
        <xyz>0 0 1</xyz>
      </axis>
    </joint>

    <joint name='caster_back_joint' type='ball'>
      <parent>base_link</parent>
      <child>caster_back_link</child>
    </joint>

    <joint name="imu_joint" type="fixed">
      <parent>base_link</parent>
      <child>imu_link</child>
      <pose>-0.32 0 0.68 0 0 0</pose>
      <axis>
        <xyz>0 0 1</xyz>
      </axis>
    </joint>

    <joint name="lidar_joint" type="fixed">
      <parent>base_link</parent>
      <child>base_scan</child>
      <pose>-0.32 0 1.71 0 0 0</pose>
      <axis>
        <xyz>0 0 1</xyz>
      </axis>
    </joint>

    <plugin filename="libignition-gazebo-diff-drive-system.so"
     name="ignition::gazebo::systems::DiffDrive">

      <ros>
        <!-- <namespace>/tb3</namespace> -->
      </ros>

      <update_rate>30</update_rate>

      <!-- wheels -->
      <left_joint>wheel_left_joint</left_joint>
      <right_joint>wheel_right_joint</right_joint>

      <!-- kinematics -->
      <wheel_separation>1.60</wheel_separation>
      <wheel_diameter>0.66</wheel_diameter>

      <!-- limits -->
      <max_wheel_torque>2000</max_wheel_torque>
      <max_wheel_acceleration>10.0</max_wheel_acceleration>

      <command_topic>cmd_vel</command_topic>

      <!-- output -->
      <publish_odom>true</publish_odom>
      <publish_odom_tf>true</publish_odom_tf>
      <publish_wheel_tf>false</publish_wheel_tf>

      <odometry_topic>odom</odometry_topic>
      <odometry_frame>odom</odometry_frame>
      <robot_base_frame>base_footprint</robot_base_frame>

    </plugin>

     <plugin filename="libignition-gazebo-joint-state-publisher-system.so" 
     name="ignition::gazebo::systems::JointStatePublisher"> 
      <ros>
        <!-- <namespace>/tb3</namespace> -->
        <remapping>~/out:=joint_states</remapping>
      </ros>
      <update_rate>30</update_rate>
      <joint_name>wheel_left_joint</joint_name>
      <joint_name>wheel_right_joint</joint_name>
    </plugin>      
  </model>
</sdf>